#VRML_SIM R2025a utf8

EXTERNPROTO "https://raw.githubusercontent.com/cyberbotics/webots/R2025a/projects/objects/backgrounds/protos/TexturedBackground.proto"
EXTERNPROTO "https://raw.githubusercontent.com/cyberbotics/webots/R2025a/projects/objects/backgrounds/protos/TexturedBackgroundLight.proto"
EXTERNPROTO "https://raw.githubusercontent.com/cyberbotics/webots/R2025a/projects/objects/floors/protos/RectangleArena.proto"
EXTERNPROTO "https://raw.githubusercontent.com/cyberbotics/webots/R2025a/projects/objects/factory/containers/protos/WoodenBox.proto"

WorldInfo {
}
Viewpoint {
  orientation 0.6121543945743271 0.08030214099791243 -0.7866502166493633 2.6827193104125375
  position 1.380757701879212 2.437142834054749 9.13248754057644
}
TexturedBackground {
}
TexturedBackgroundLight {
}
RectangleArena {
  floorSize 5 5
}
Robot {
  translation -2.25 -0.25 0.0397031
  children [
    HingeJoint {
      jointParameters HingeJointParameters {
        position 408.27761373779555
        axis 0 1 0
        anchor 0.05 0.06 0
      }
      device [
        RotationalMotor {
          name "motor1"
        }
      ]
      endPoint Solid {
        translation 0.0500098122347557 0.06000067095540662 -5.455707588047639e-06
        rotation -0.9958264627324172 0.06453866512172883 -0.06453229289392248 4.708198682207355
        children [
          DEF Rueda Shape {
            appearance PBRAppearance {
              baseColor 0 1 0
              metalness 0
            }
            geometry Cylinder {
              height 0.02
              radius 0.04
            }
          }
        ]
        name "rueda1"
        boundingObject USE Rueda
        physics Physics {
        }
      }
    }
    HingeJoint {
      jointParameters HingeJointParameters {
        position 338.11206356512434
        axis 0 1 0
        anchor 0.05 -0.06 0
      }
      device [
        RotationalMotor {
          name "motor2"
        }
      ]
      endPoint Solid {
        translation 0.05001249536424314 -0.059999283239963785 -6.20404510819023e-06
        rotation -0.726146445193021 0.4861667319829026 -0.4861617517314618 4.397706249886574
        children [
          USE Rueda
        ]
        name "rueda2"
        boundingObject USE Rueda
        physics Physics {
        }
      }
    }
    HingeJoint {
      jointParameters HingeJointParameters {
        position 357.08215280193633
        axis 0 1 0
        anchor -0.05 -0.06 0
      }
      device [
        RotationalMotor {
          name "motor3"
        }
      ]
      endPoint Solid {
        translation -0.049990719032170484 -0.0600006734943581 -6.436809490838355e-06
        rotation 0.7702191414073273 -0.45098080411201696 0.45097537464060977 1.8289643586007773
        children [
          USE Rueda
        ]
        name "rueda3"
        boundingObject USE Rueda
        physics Physics {
        }
      }
    }
    HingeJoint {
      jointParameters HingeJointParameters {
        position 389.30754818121534
        axis 0 1 0
        anchor -0.05 0.06 0
      }
      device [
        RotationalMotor {
          name "motor4"
        }
      ]
      endPoint Solid {
        translation -0.0499871130854888 0.059999282978267565 -5.430028488803895e-06
        rotation 0.984582488143259 -0.12369070389517509 0.12368481641472885 1.586341627892727
        children [
          USE Rueda
        ]
        name "rueda4"
        boundingObject USE Rueda
        physics Physics {
        }
      }
    }
    DEF Cuerpo Shape {
      appearance PBRAppearance {
        baseColor 1 0 0
        metalness 0
      }
      geometry Box {
        size 0.2 0.1 0.05
      }
    }
    InertialUnit {
      translation 0.1 0 0.05
      children [
        DEF IMU Shape {
          appearance PBRAppearance {
            metalness 0
          }
          geometry Cone {
            bottomRadius 0.02
            height 0.03
          }
        }
      ]
      name "imu"
      boundingObject Shape {
        appearance PBRAppearance {
        }
        geometry Box {
          size 0.05 0.05 0.05
        }
      }
      physics Physics {
      }
    }
    Lidar {
      translation 0 0 0.08
      children [
        DEF Lidar Shape {
          appearance PBRAppearance {
            baseColor 0.3 0.5 0.5
            metalness 0
          }
          geometry Box {
            size 0.01 0.01 0.01
          }
        }
      ]
      boundingObject USE Lidar
      physics Physics {
      }
      horizontalResolution 128
      fieldOfView 0.25
      verticalFieldOfView 0.1
      numberOfLayers 1
    }
    Display {
    }
    GPS {
      translation 0 0 0.05
      children [
        DEF GPS Shape {
          appearance PBRAppearance {
            baseColor 0.6 0.5 0.3
          }
          geometry Cylinder {
            height 0.05
            radius 0.02
          }
        }
      ]
      boundingObject USE GPS
      physics Physics {
      }
    }
    DistanceSensor {
      translation 0.1 0.02 0
      rotation 0 0 1 0.3
      children [
        DEF sensorDistancia Shape {
          appearance PBRAppearance {
            baseColor 0 0 1
            metalness 0
          }
          geometry Box {
            size 0.01 0.01 0.01
          }
        }
      ]
      name "distIzq"
      boundingObject USE sensorDistancia
      physics Physics {
      }
    }
    DistanceSensor {
      translation 0.1 -0.02 0
      rotation 0 0 1 -0.3
      children [
        USE sensorDistancia
      ]
      name "distDer"
      boundingObject USE sensorDistancia
      physics Physics {
      }
    }
  ]
  boundingObject USE Cuerpo
  physics Physics {
  }
  controller "my_controller"
  window "<none>"
}
WoodenBox {
  translation -0.23 -0.24 0.3
  size 0.5 0.5 0.5
}
WoodenBox {
  translation -2.27 2.24 0.3
  name "wooden box(1)"
  size 0.5 0.5 0.5
}
