#VRML_SIM R2025a utf8

EXTERNPROTO "https://raw.githubusercontent.com/cyberbotics/webots/R2025a/projects/objects/backgrounds/protos/TexturedBackground.proto"
EXTERNPROTO "https://raw.githubusercontent.com/cyberbotics/webots/R2025a/projects/objects/backgrounds/protos/TexturedBackgroundLight.proto"
EXTERNPROTO "https://raw.githubusercontent.com/cyberbotics/webots/R2025a/projects/objects/floors/protos/RectangleArena.proto"
EXTERNPROTO "https://raw.githubusercontent.com/cyberbotics/webots/R2025a/projects/objects/factory/containers/protos/WoodenBox.proto"

WorldInfo {
}
Viewpoint {
  orientation 0.1952524135287916 -0.08707647334439075 -0.9768798200398479 3.963304593148477
  position 4.4954583843399165 -6.106429984001566 3.3733408585357587
}
TexturedBackground {
}
TexturedBackgroundLight {
}
RectangleArena {
  floorSize 5 5
}
Robot {
  translation 0 0 0.0397031
  rotation 0.001214870299984249 0.00017388504293690775 -0.9999992469267897 -0.02882530717958609
  children [
    HingeJoint {
      jointParameters HingeJointParameters {
        position 224.8127318172125
        axis 0 1 0
        anchor 0.05 0.06 0
      }
      device [
        RotationalMotor {
          name "motor1"
        }
      ]
      endPoint Solid {
        translation 0.05000036744285621 0.060000260355453916 2.149945967412814e-07
        rotation -0.6498795868920676 0.5374270614749451 -0.537427833420824 4.294167093818385
        children [
          DEF Rueda Shape {
            appearance PBRAppearance {
              baseColor 0 1 0
              metalness 0
            }
            geometry Cylinder {
              height 0.02
              radius 0.04
            }
          }
        ]
        name "rueda1"
        boundingObject USE Rueda
        physics Physics {
        }
      }
    }
    HingeJoint {
      jointParameters HingeJointParameters {
        position 173.6172631820924
        axis 0 1 0
        anchor 0.05 -0.06 0
      }
      device [
        RotationalMotor {
          name "motor2"
        }
      ]
      endPoint Solid {
        translation 0.05000452601792477 -0.0599996937541237 3.967625395409499e-07
        rotation 0.297321526262121 -0.675129295211573 0.6751298725195676 2.5636016142081948
        children [
          USE Rueda
        ]
        name "rueda2"
        boundingObject USE Rueda
        physics Physics {
        }
      }
    }
    HingeJoint {
      jointParameters HingeJointParameters {
        position 173.61727191872484
        axis 0 1 0
        anchor -0.05 -0.06 0
      }
      device [
        RotationalMotor {
          name "motor3"
        }
      ]
      endPoint Solid {
        translation -0.049998509800026576 -0.06000026297843092 -1.4741468503770884e-06
        rotation 0.29732479030252296 -0.6751286417336344 0.6751290885323034 2.5635955487709947
        children [
          USE Rueda
        ]
        name "rueda3"
        boundingObject USE Rueda
        physics Physics {
        }
      }
    }
    HingeJoint {
      jointParameters HingeJointParameters {
        position 224.81274137329703
        axis 0 1 0
        anchor -0.05 0.06 0
      }
      device [
        RotationalMotor {
          name "motor4"
        }
      ]
      endPoint Solid {
        translation -0.049995629878574484 0.05999969365514608 1.1076872791359201e-06
        rotation -0.6498832853181681 0.5374248742171395 -0.5374255483662423 4.294172433650379
        children [
          USE Rueda
        ]
        name "rueda4"
        boundingObject USE Rueda
        physics Physics {
        }
      }
    }
    DEF Cuerpo Shape {
      appearance PBRAppearance {
        baseColor 1 0 0
        metalness 0
      }
      geometry Box {
        size 0.2 0.1 0.05
      }
    }
    Lidar {
      translation 0 0 0.06
      children [
        DEF Lidar Shape {
          appearance PBRAppearance {
            metalness 0
          }
          geometry Cylinder {
            height 0.08
            radius 0.05
          }
        }
      ]
      boundingObject USE Lidar
      physics Physics {
      }
      numberOfLayers 1
      maxRange 0.8
    }
    Display {
    }
    GPS {
    }
    DistanceSensor {
      translation 0.1 0.02 0
      rotation 0 0 1 0.3
      children [
        DEF sensorDistancia Shape {
          appearance PBRAppearance {
            baseColor 0 0 1
            metalness 0
          }
          geometry Box {
            size 0.01 0.01 0.01
          }
        }
      ]
      name "distIzq"
      boundingObject USE sensorDistancia
      physics Physics {
      }
    }
    DistanceSensor {
      translation 0.1 -0.02 0
      rotation 0 0 1 -0.3
      children [
        USE sensorDistancia
      ]
      name "distDer"
      boundingObject USE sensorDistancia
      physics Physics {
      }
    }
  ]
  boundingObject USE Cuerpo
  physics Physics {
  }
  controller "my_controller"
}
WoodenBox {
  translation 0 1.54 0.3
}
